[2022-08-17 18:35:05,712] {taskinstance.py:1159} INFO - Dependencies all met for <TaskInstance: Deepface.validate manual__2022-08-17T18:28:34.879124+00:00 [queued]>
[2022-08-17 18:35:05,935] {taskinstance.py:1159} INFO - Dependencies all met for <TaskInstance: Deepface.validate manual__2022-08-17T18:28:34.879124+00:00 [queued]>
[2022-08-17 18:35:05,935] {taskinstance.py:1356} INFO - 
--------------------------------------------------------------------------------
[2022-08-17 18:35:05,935] {taskinstance.py:1357} INFO - Starting attempt 2 of 2
[2022-08-17 18:35:05,936] {taskinstance.py:1358} INFO - 
--------------------------------------------------------------------------------
[2022-08-17 18:35:05,964] {taskinstance.py:1377} INFO - Executing <Task(PythonOperator): validate> on 2022-08-17 18:28:34.879124+00:00
[2022-08-17 18:35:05,978] {standard_task_runner.py:52} INFO - Started process 63 to run task
[2022-08-17 18:35:05,982] {standard_task_runner.py:79} INFO - Running: ['***', 'tasks', 'run', 'Deepface', 'validate', 'manual__2022-08-17T18:28:34.879124+00:00', '--job-id', '38', '--raw', '--subdir', 'DAGS_FOLDER/deepface.py', '--cfg-path', '/tmp/tmp3iyy8utl', '--error-file', '/tmp/tmp_xk0d51x']
[2022-08-17 18:35:05,984] {standard_task_runner.py:80} INFO - Job 38: Subtask validate
[2022-08-17 18:35:06,089] {task_command.py:370} INFO - Running <TaskInstance: Deepface.validate manual__2022-08-17T18:28:34.879124+00:00 [running]> on host d254c144b912
[2022-08-17 18:35:06,270] {taskinstance.py:1571} INFO - Exporting the following env vars:
AIRFLOW_CTX_DAG_EMAIL=***@example.com
AIRFLOW_CTX_DAG_OWNER=***
AIRFLOW_CTX_DAG_ID=Deepface
AIRFLOW_CTX_TASK_ID=validate
AIRFLOW_CTX_EXECUTION_DATE=2022-08-17T18:28:34.879124+00:00
AIRFLOW_CTX_TRY_NUMBER=2
AIRFLOW_CTX_DAG_RUN_ID=manual__2022-08-17T18:28:34.879124+00:00
[2022-08-17 18:35:06,287] {taskinstance.py:1889} ERROR - Task failed with exception
Traceback (most recent call last):
  File "/home/airflow/.local/lib/python3.7/site-packages/airflow/operators/python.py", line 171, in execute
    return_value = self.execute_callable()
  File "/home/airflow/.local/lib/python3.7/site-packages/airflow/operators/python.py", line 189, in execute_callable
    return self.python_callable(*self.op_args, **self.op_kwargs)
  File "/opt/airflow/dags/deepface.py", line 79, in _validate
    client = MongoClient(Variable.get("MONGO_URL"))
  File "/home/airflow/.local/lib/python3.7/site-packages/airflow/models/variable.py", line 138, in get
    raise KeyError(f'Variable {key} does not exist')
KeyError: 'Variable MONGO_URL does not exist'
[2022-08-17 18:35:06,329] {taskinstance.py:1400} INFO - Marking task as FAILED. dag_id=Deepface, task_id=validate, execution_date=20220817T182834, start_date=20220817T183505, end_date=20220817T183506
[2022-08-17 18:35:06,350] {standard_task_runner.py:97} ERROR - Failed to execute job 38 for task validate ('Variable MONGO_URL does not exist'; 63)
[2022-08-17 18:35:06,406] {local_task_job.py:156} INFO - Task exited with return code 1
[2022-08-17 18:35:06,466] {local_task_job.py:273} INFO - 0 downstream tasks scheduled from follow-on schedule check
