[2022-08-17 19:21:53,230] {taskinstance.py:1159} INFO - Dependencies all met for <TaskInstance: Deepface.validate manual__2022-08-17T19:21:48.787316+00:00 [queued]>
[2022-08-17 19:21:53,409] {taskinstance.py:1159} INFO - Dependencies all met for <TaskInstance: Deepface.validate manual__2022-08-17T19:21:48.787316+00:00 [queued]>
[2022-08-17 19:21:53,409] {taskinstance.py:1356} INFO - 
--------------------------------------------------------------------------------
[2022-08-17 19:21:53,409] {taskinstance.py:1357} INFO - Starting attempt 1 of 2
[2022-08-17 19:21:53,409] {taskinstance.py:1358} INFO - 
--------------------------------------------------------------------------------
[2022-08-17 19:21:53,429] {taskinstance.py:1377} INFO - Executing <Task(PythonOperator): validate> on 2022-08-17 19:21:48.787316+00:00
[2022-08-17 19:21:53,444] {standard_task_runner.py:52} INFO - Started process 1447 to run task
[2022-08-17 19:21:53,449] {standard_task_runner.py:79} INFO - Running: ['***', 'tasks', 'run', 'Deepface', 'validate', 'manual__2022-08-17T19:21:48.787316+00:00', '--job-id', '49', '--raw', '--subdir', 'DAGS_FOLDER/deepface.py', '--cfg-path', '/tmp/tmptf29bljc', '--error-file', '/tmp/tmp3ozlb9nb']
[2022-08-17 19:21:53,459] {standard_task_runner.py:80} INFO - Job 49: Subtask validate
[2022-08-17 19:21:53,584] {task_command.py:370} INFO - Running <TaskInstance: Deepface.validate manual__2022-08-17T19:21:48.787316+00:00 [running]> on host d254c144b912
[2022-08-17 19:21:53,731] {taskinstance.py:1571} INFO - Exporting the following env vars:
AIRFLOW_CTX_DAG_EMAIL=***@example.com
AIRFLOW_CTX_DAG_OWNER=***
AIRFLOW_CTX_DAG_ID=Deepface
AIRFLOW_CTX_TASK_ID=validate
AIRFLOW_CTX_EXECUTION_DATE=2022-08-17T19:21:48.787316+00:00
AIRFLOW_CTX_TRY_NUMBER=1
AIRFLOW_CTX_DAG_RUN_ID=manual__2022-08-17T19:21:48.787316+00:00
[2022-08-17 19:22:00,842] {logging_mixin.py:115} INFO - 1/1 [==============================] - ETA: 0s
[2022-08-17 19:22:00,843] {logging_mixin.py:115} INFO - 1/1 [==============================] - 1s 525ms/step
[2022-08-17 19:22:01,388] {logging_mixin.py:115} INFO - 1/1 [==============================] - ETA: 0s
[2022-08-17 19:22:01,388] {logging_mixin.py:115} INFO - 1/1 [==============================] - 0s 446ms/step
[2022-08-17 19:22:02,558] {taskinstance.py:1889} ERROR - Task failed with exception
Traceback (most recent call last):
  File "/home/airflow/.local/lib/python3.7/site-packages/airflow/operators/python.py", line 171, in execute
    return_value = self.execute_callable()
  File "/home/airflow/.local/lib/python3.7/site-packages/airflow/operators/python.py", line 189, in execute_callable
    return self.python_callable(*self.op_args, **self.op_kwargs)
  File "/opt/airflow/dags/deepface.py", line 101, in _validate
    notify_unvalidated(exam['email'], exam['course'], not_verified)
TypeError: 'NoneType' object is not subscriptable
[2022-08-17 19:22:02,578] {taskinstance.py:1400} INFO - Marking task as UP_FOR_RETRY. dag_id=Deepface, task_id=validate, execution_date=20220817T192148, start_date=20220817T192153, end_date=20220817T192202
[2022-08-17 19:22:02,611] {standard_task_runner.py:97} ERROR - Failed to execute job 49 for task validate ('NoneType' object is not subscriptable; 1447)
[2022-08-17 19:22:02,709] {local_task_job.py:156} INFO - Task exited with return code 1
[2022-08-17 19:22:02,749] {local_task_job.py:273} INFO - 0 downstream tasks scheduled from follow-on schedule check
