[2022-08-17 19:44:11,232] {taskinstance.py:1159} INFO - Dependencies all met for <TaskInstance: Deepface.validate manual__2022-08-17T19:44:07.158458+00:00 [queued]>
[2022-08-17 19:44:11,426] {taskinstance.py:1159} INFO - Dependencies all met for <TaskInstance: Deepface.validate manual__2022-08-17T19:44:07.158458+00:00 [queued]>
[2022-08-17 19:44:11,426] {taskinstance.py:1356} INFO - 
--------------------------------------------------------------------------------
[2022-08-17 19:44:11,426] {taskinstance.py:1357} INFO - Starting attempt 1 of 2
[2022-08-17 19:44:11,426] {taskinstance.py:1358} INFO - 
--------------------------------------------------------------------------------
[2022-08-17 19:44:11,444] {taskinstance.py:1377} INFO - Executing <Task(PythonOperator): validate> on 2022-08-17 19:44:07.158458+00:00
[2022-08-17 19:44:11,453] {standard_task_runner.py:52} INFO - Started process 2596 to run task
[2022-08-17 19:44:11,456] {standard_task_runner.py:79} INFO - Running: ['***', 'tasks', 'run', 'Deepface', 'validate', 'manual__2022-08-17T19:44:07.158458+00:00', '--job-id', '53', '--raw', '--subdir', 'DAGS_FOLDER/deepface.py', '--cfg-path', '/tmp/tmpsjngtdd5', '--error-file', '/tmp/tmpiiw_syac']
[2022-08-17 19:44:11,458] {standard_task_runner.py:80} INFO - Job 53: Subtask validate
[2022-08-17 19:44:11,522] {task_command.py:370} INFO - Running <TaskInstance: Deepface.validate manual__2022-08-17T19:44:07.158458+00:00 [running]> on host d254c144b912
[2022-08-17 19:44:11,628] {taskinstance.py:1571} INFO - Exporting the following env vars:
AIRFLOW_CTX_DAG_EMAIL=***@example.com
AIRFLOW_CTX_DAG_OWNER=***
AIRFLOW_CTX_DAG_ID=Deepface
AIRFLOW_CTX_TASK_ID=validate
AIRFLOW_CTX_EXECUTION_DATE=2022-08-17T19:44:07.158458+00:00
AIRFLOW_CTX_TRY_NUMBER=1
AIRFLOW_CTX_DAG_RUN_ID=manual__2022-08-17T19:44:07.158458+00:00
[2022-08-17 19:44:19,752] {logging_mixin.py:115} INFO - 1/1 [==============================] - ETA: 0s
[2022-08-17 19:44:19,752] {logging_mixin.py:115} INFO - 1/1 [==============================] - 1s 950ms/step
[2022-08-17 19:44:20,472] {logging_mixin.py:115} INFO - 1/1 [==============================] - ETA: 0s
[2022-08-17 19:44:20,473] {logging_mixin.py:115} INFO - 1/1 [==============================] - 1s 517ms/step
[2022-08-17 19:44:21,637] {taskinstance.py:1889} ERROR - Task failed with exception
Traceback (most recent call last):
  File "/home/airflow/.local/lib/python3.7/site-packages/airflow/operators/python.py", line 171, in execute
    return_value = self.execute_callable()
  File "/home/airflow/.local/lib/python3.7/site-packages/airflow/operators/python.py", line 189, in execute_callable
    return self.python_callable(*self.op_args, **self.op_kwargs)
  File "/opt/airflow/dags/deepface.py", line 101, in _validate
    notify_unvalidated(not_verified)
  File "/opt/airflow/dags/deepface.py", line 42, in notify_unvalidated
    for mail,students_to_verify in not_verified:
ValueError: too many values to unpack (expected 2)
[2022-08-17 19:44:21,655] {taskinstance.py:1400} INFO - Marking task as UP_FOR_RETRY. dag_id=Deepface, task_id=validate, execution_date=20220817T194407, start_date=20220817T194411, end_date=20220817T194421
[2022-08-17 19:44:21,683] {standard_task_runner.py:97} ERROR - Failed to execute job 53 for task validate (too many values to unpack (expected 2); 2596)
[2022-08-17 19:44:21,836] {local_task_job.py:156} INFO - Task exited with return code 1
[2022-08-17 19:44:21,868] {local_task_job.py:273} INFO - 0 downstream tasks scheduled from follow-on schedule check
