[2022-08-17 19:46:15,351] {taskinstance.py:1159} INFO - Dependencies all met for <TaskInstance: Deepface.validate manual__2022-08-17T19:46:09.738768+00:00 [queued]>
[2022-08-17 19:46:15,538] {taskinstance.py:1159} INFO - Dependencies all met for <TaskInstance: Deepface.validate manual__2022-08-17T19:46:09.738768+00:00 [queued]>
[2022-08-17 19:46:15,538] {taskinstance.py:1356} INFO - 
--------------------------------------------------------------------------------
[2022-08-17 19:46:15,538] {taskinstance.py:1357} INFO - Starting attempt 1 of 2
[2022-08-17 19:46:15,538] {taskinstance.py:1358} INFO - 
--------------------------------------------------------------------------------
[2022-08-17 19:46:15,555] {taskinstance.py:1377} INFO - Executing <Task(PythonOperator): validate> on 2022-08-17 19:46:09.738768+00:00
[2022-08-17 19:46:15,564] {standard_task_runner.py:52} INFO - Started process 2723 to run task
[2022-08-17 19:46:15,568] {standard_task_runner.py:79} INFO - Running: ['***', 'tasks', 'run', 'Deepface', 'validate', 'manual__2022-08-17T19:46:09.738768+00:00', '--job-id', '54', '--raw', '--subdir', 'DAGS_FOLDER/deepface.py', '--cfg-path', '/tmp/tmpg02k29yg', '--error-file', '/tmp/tmpm6frykey']
[2022-08-17 19:46:15,569] {standard_task_runner.py:80} INFO - Job 54: Subtask validate
[2022-08-17 19:46:15,628] {task_command.py:370} INFO - Running <TaskInstance: Deepface.validate manual__2022-08-17T19:46:09.738768+00:00 [running]> on host d254c144b912
[2022-08-17 19:46:15,718] {taskinstance.py:1571} INFO - Exporting the following env vars:
AIRFLOW_CTX_DAG_EMAIL=***@example.com
AIRFLOW_CTX_DAG_OWNER=***
AIRFLOW_CTX_DAG_ID=Deepface
AIRFLOW_CTX_TASK_ID=validate
AIRFLOW_CTX_EXECUTION_DATE=2022-08-17T19:46:09.738768+00:00
AIRFLOW_CTX_TRY_NUMBER=1
AIRFLOW_CTX_DAG_RUN_ID=manual__2022-08-17T19:46:09.738768+00:00
[2022-08-17 19:46:23,033] {logging_mixin.py:115} INFO - 1/1 [==============================] - ETA: 0s
[2022-08-17 19:46:23,034] {logging_mixin.py:115} INFO - 1/1 [==============================] - 1s 522ms/step
[2022-08-17 19:46:23,458] {logging_mixin.py:115} INFO - 1/1 [==============================] - ETA: 0s
[2022-08-17 19:46:23,459] {logging_mixin.py:115} INFO - 1/1 [==============================] - 0s 310ms/step
[2022-08-17 19:46:24,602] {taskinstance.py:1889} ERROR - Task failed with exception
Traceback (most recent call last):
  File "/home/airflow/.local/lib/python3.7/site-packages/airflow/operators/python.py", line 171, in execute
    return_value = self.execute_callable()
  File "/home/airflow/.local/lib/python3.7/site-packages/airflow/operators/python.py", line 189, in execute_callable
    return self.python_callable(*self.op_args, **self.op_kwargs)
  File "/opt/airflow/dags/deepface.py", line 101, in _validate
    notify_unvalidated(not_verified)
  File "/opt/airflow/dags/deepface.py", line 49, in notify_unvalidated
    for name,email in not_verified:
ValueError: too many values to unpack (expected 2)
[2022-08-17 19:46:24,611] {taskinstance.py:1400} INFO - Marking task as UP_FOR_RETRY. dag_id=Deepface, task_id=validate, execution_date=20220817T194609, start_date=20220817T194615, end_date=20220817T194624
[2022-08-17 19:46:24,645] {standard_task_runner.py:97} ERROR - Failed to execute job 54 for task validate (too many values to unpack (expected 2); 2723)
[2022-08-17 19:46:24,760] {local_task_job.py:156} INFO - Task exited with return code 1
[2022-08-17 19:46:24,852] {local_task_job.py:273} INFO - 0 downstream tasks scheduled from follow-on schedule check
