[2022-08-17 18:35:14,968] {taskinstance.py:1159} INFO - Dependencies all met for <TaskInstance: Deepface.validate manual__2022-08-17T18:35:10.914478+00:00 [queued]>
[2022-08-17 18:35:15,154] {taskinstance.py:1159} INFO - Dependencies all met for <TaskInstance: Deepface.validate manual__2022-08-17T18:35:10.914478+00:00 [queued]>
[2022-08-17 18:35:15,154] {taskinstance.py:1356} INFO - 
--------------------------------------------------------------------------------
[2022-08-17 18:35:15,154] {taskinstance.py:1357} INFO - Starting attempt 1 of 2
[2022-08-17 18:35:15,154] {taskinstance.py:1358} INFO - 
--------------------------------------------------------------------------------
[2022-08-17 18:35:15,171] {taskinstance.py:1377} INFO - Executing <Task(PythonOperator): validate> on 2022-08-17 18:35:10.914478+00:00
[2022-08-17 18:35:15,178] {standard_task_runner.py:52} INFO - Started process 75 to run task
[2022-08-17 18:35:15,182] {standard_task_runner.py:79} INFO - Running: ['***', 'tasks', 'run', 'Deepface', 'validate', 'manual__2022-08-17T18:35:10.914478+00:00', '--job-id', '39', '--raw', '--subdir', 'DAGS_FOLDER/deepface.py', '--cfg-path', '/tmp/tmpgfef5y6u', '--error-file', '/tmp/tmp5r2lwwci']
[2022-08-17 18:35:15,183] {standard_task_runner.py:80} INFO - Job 39: Subtask validate
[2022-08-17 18:35:15,234] {task_command.py:370} INFO - Running <TaskInstance: Deepface.validate manual__2022-08-17T18:35:10.914478+00:00 [running]> on host d254c144b912
[2022-08-17 18:35:15,326] {taskinstance.py:1571} INFO - Exporting the following env vars:
AIRFLOW_CTX_DAG_EMAIL=***@example.com
AIRFLOW_CTX_DAG_OWNER=***
AIRFLOW_CTX_DAG_ID=Deepface
AIRFLOW_CTX_TASK_ID=validate
AIRFLOW_CTX_EXECUTION_DATE=2022-08-17T18:35:10.914478+00:00
AIRFLOW_CTX_TRY_NUMBER=1
AIRFLOW_CTX_DAG_RUN_ID=manual__2022-08-17T18:35:10.914478+00:00
[2022-08-17 18:35:15,337] {taskinstance.py:1889} ERROR - Task failed with exception
Traceback (most recent call last):
  File "/home/airflow/.local/lib/python3.7/site-packages/airflow/operators/python.py", line 171, in execute
    return_value = self.execute_callable()
  File "/home/airflow/.local/lib/python3.7/site-packages/airflow/operators/python.py", line 189, in execute_callable
    return self.python_callable(*self.op_args, **self.op_kwargs)
  File "/opt/airflow/dags/deepface.py", line 79, in _validate
    client = MongoClient(Variable.get("MONGO_URL"))
  File "/home/airflow/.local/lib/python3.7/site-packages/airflow/models/variable.py", line 138, in get
    raise KeyError(f'Variable {key} does not exist')
KeyError: 'Variable MONGO_URL does not exist'
[2022-08-17 18:35:15,348] {taskinstance.py:1400} INFO - Marking task as UP_FOR_RETRY. dag_id=Deepface, task_id=validate, execution_date=20220817T183510, start_date=20220817T183514, end_date=20220817T183515
[2022-08-17 18:35:15,367] {standard_task_runner.py:97} ERROR - Failed to execute job 39 for task validate ('Variable MONGO_URL does not exist'; 75)
[2022-08-17 18:35:15,394] {local_task_job.py:156} INFO - Task exited with return code 1
[2022-08-17 18:35:15,430] {local_task_job.py:273} INFO - 0 downstream tasks scheduled from follow-on schedule check
