[2022-08-17 18:40:19,573] {taskinstance.py:1159} INFO - Dependencies all met for <TaskInstance: Deepface.validate manual__2022-08-17T18:35:10.914478+00:00 [queued]>
[2022-08-17 18:40:20,060] {taskinstance.py:1159} INFO - Dependencies all met for <TaskInstance: Deepface.validate manual__2022-08-17T18:35:10.914478+00:00 [queued]>
[2022-08-17 18:40:20,060] {taskinstance.py:1356} INFO - 
--------------------------------------------------------------------------------
[2022-08-17 18:40:20,060] {taskinstance.py:1357} INFO - Starting attempt 2 of 2
[2022-08-17 18:40:20,060] {taskinstance.py:1358} INFO - 
--------------------------------------------------------------------------------
[2022-08-17 18:40:20,090] {taskinstance.py:1377} INFO - Executing <Task(PythonOperator): validate> on 2022-08-17 18:35:10.914478+00:00
[2022-08-17 18:40:20,105] {standard_task_runner.py:52} INFO - Started process 337 to run task
[2022-08-17 18:40:20,121] {standard_task_runner.py:79} INFO - Running: ['***', 'tasks', 'run', 'Deepface', 'validate', 'manual__2022-08-17T18:35:10.914478+00:00', '--job-id', '41', '--raw', '--subdir', 'DAGS_FOLDER/deepface.py', '--cfg-path', '/tmp/tmpex5qc7zd', '--error-file', '/tmp/tmpfy5jvkgo']
[2022-08-17 18:40:20,129] {standard_task_runner.py:80} INFO - Job 41: Subtask validate
[2022-08-17 18:40:20,242] {task_command.py:370} INFO - Running <TaskInstance: Deepface.validate manual__2022-08-17T18:35:10.914478+00:00 [running]> on host d254c144b912
[2022-08-17 18:40:20,467] {taskinstance.py:1571} INFO - Exporting the following env vars:
AIRFLOW_CTX_DAG_EMAIL=***@example.com
AIRFLOW_CTX_DAG_OWNER=***
AIRFLOW_CTX_DAG_ID=Deepface
AIRFLOW_CTX_TASK_ID=validate
AIRFLOW_CTX_EXECUTION_DATE=2022-08-17T18:35:10.914478+00:00
AIRFLOW_CTX_TRY_NUMBER=2
AIRFLOW_CTX_DAG_RUN_ID=manual__2022-08-17T18:35:10.914478+00:00
[2022-08-17 18:40:28,422] {logging_mixin.py:115} INFO - 1/1 [==============================] - ETA: 0s
[2022-08-17 18:40:28,423] {logging_mixin.py:115} INFO - 1/1 [==============================] - 1s 780ms/step
[2022-08-17 18:40:28,952] {logging_mixin.py:115} INFO - 1/1 [==============================] - ETA: 0s
[2022-08-17 18:40:28,952] {logging_mixin.py:115} INFO - 1/1 [==============================] - 0s 408ms/step
[2022-08-17 18:40:30,088] {taskinstance.py:1889} ERROR - Task failed with exception
Traceback (most recent call last):
  File "/home/airflow/.local/lib/python3.7/site-packages/airflow/operators/python.py", line 171, in execute
    return_value = self.execute_callable()
  File "/home/airflow/.local/lib/python3.7/site-packages/airflow/operators/python.py", line 189, in execute_callable
    return self.python_callable(*self.op_args, **self.op_kwargs)
  File "/opt/airflow/dags/deepface.py", line 105, in _validate
    notify_unvalidated(not_verified)
TypeError: notify_unvalidated() takes 0 positional arguments but 1 was given
[2022-08-17 18:40:30,102] {taskinstance.py:1400} INFO - Marking task as FAILED. dag_id=Deepface, task_id=validate, execution_date=20220817T183510, start_date=20220817T184019, end_date=20220817T184030
[2022-08-17 18:40:30,128] {standard_task_runner.py:97} ERROR - Failed to execute job 41 for task validate (notify_unvalidated() takes 0 positional arguments but 1 was given; 337)
[2022-08-17 18:40:30,293] {local_task_job.py:156} INFO - Task exited with return code 1
[2022-08-17 18:40:30,397] {local_task_job.py:273} INFO - 0 downstream tasks scheduled from follow-on schedule check
